{
    "registryname": "oh",
	"localizedname": "欧皇检测器",
	"requires-blueprint": false,
	"color": "adadff",
    "parts": [
        {
            "x": -2,
            "y": 0,
            "z": 2,
            
            "elements": [
                "modularmachinery:blockcasing@4"
            ]
        },
        {
            "x": -1,
            "y": 2,
            "z": 3,
            
            "elements": [
                "modularmachinery:blockcasing@3"
            ]
        },
        {
            "x": -2,
            "y": 2,
            "z": 5,
            "elements": [
                "additions:bxloveu-diamond_block@0"
            ]
        },
        {
            "x": 2,
            "y": 2,
            "z": 1,
            "elements": [
                "additions:bxloveu-diamond_block@0"
            ]
        },
        {
            "x": -1,
            "y": 0,
            "z": 2,
            "elements": [
                "astralsorcery:fluidblockliquidstarlight@0"
            ]
        },
        {
            "x": 0,
            "y": 2,
            "z": 3,
            "elements": [
                "additions:bxloveu-diamond_block@0"
            ]
        },
        {
            "x": -2,
            "y": 0,
            "z": 4,
            
            "elements": [
                "modularmachinery:blockcasing@4"
            ]
        },
        {
            "x": 0,
            "y": 0,
            "z": 2,
            "elements": [
                "astralsorcery:fluidblockliquidstarlight@0"
            ]
        },
        {
            "x": 1,
            "y": 2,
            "z": 3,
            
            "elements": [
                "modularmachinery:blockcasing@3"
            ]
        },
        {
            "x": -1,
            "y": 0,
            "z": 4,
            "elements": [
                "astralsorcery:fluidblockliquidstarlight@0"
            ]
        },
        {
            "x": 1,
            "y": 0,
            "z": 2,
            "elements": [
                "astralsorcery:fluidblockliquidstarlight@0"
            ]
        },
        {
            "x": 2,
            "y": 0,
            "z": 2,
            
            "elements": [
                "modularmachinery:blockcasing@4"
            ]
        },
        {
            "x": 0,
            "y": 0,
            "z": 4,
            "elements": [
                "astralsorcery:fluidblockliquidstarlight@0"
            ]
        },
        {
            "x": 2,
            "y": 2,
            "z": 5,
            "elements": [
                "additions:bxloveu-diamond_block@0"
            ]
        },
        {
            "x": 1,
            "y": 0,
            "z": 4,
            "elements": [
                "astralsorcery:fluidblockliquidstarlight@0"
            ]
        },
        {
            "x": 2,
            "y": 0,
            "z": 4,
            
            "elements": [
                "modularmachinery:blockcasing@4"
            ]
        },
        {
            "x": 3,
            "y": -1,
            "z": 0,
            "elements": "casings_all"
        },
        {
            "x": 2,
            "y": -1,
            "z": 0,
            "elements": "casings_all"
        },
        {
            "x": 1,
            "y": -1,
            "z": 0,
            "elements": "casings_all"
        },
        {
            "x": 0,
            "y": -1,
            "z": 0,
            
            "elements": [
                "modularmachinery:blockcasing@4"
            ]
        },
        {
            "x": -1,
            "y": -1,
            "z": 0,
            "elements": "casings_all"
        },
        {
            "x": -3,
            "y": -1,
            "z": 1,
            
            "elements": [
                "modularmachinery:blockcasing@4"
            ]
        },
        {
            "x": -2,
            "y": -1,
            "z": 1,
            "elements": [
                "minecraft:gold_block@0"
            ]
        },
        {
            "x": -2,
            "y": -1,
            "z": 0,
            "elements": "casings_all"
        },
        {
            "x": 0,
            "y": 3,
            "z": 3,
            
            "elements": [
                "minecraft:beacon@0"
            ]
        },
        {
            "x": -1,
            "y": -1,
            "z": 1,
            "elements": [
                "minecraft:gold_block@0"
            ]
        },
        {
            "x": -3,
            "y": -1,
            "z": 0,
            "elements": "casings_all"
        },
        {
            "x": -3,
            "y": -1,
            "z": 3,
            
            "elements": [
                "modularmachinery:blockcasing@4"
            ]
        },
        {
            "x": -2,
            "y": -1,
            "z": 3,
            "elements": [
                "minecraft:gold_block@0"
            ]
        },
        {
            "x": 0,
            "y": -1,
            "z": 1,
            "elements": [
                "minecraft:gold_block@0"
            ]
        },
        {
            "x": 1,
            "y": -1,
            "z": 1,
            "elements": [
                "minecraft:gold_block@0"
            ]
        },
        {
            "x": -1,
            "y": -1,
            "z": 3,
            "elements": [
                "minecraft:gold_block@0"
            ]
        },
        {
            "x": -3,
            "y": -1,
            "z": 5,
            
            "elements": [
                "modularmachinery:blockcasing@4"
            ]
        },
        {
            "x": -2,
            "y": -1,
            "z": 5,
            "elements": [
                "minecraft:gold_block@0"
            ]
        },
        {
            "x": 2,
            "y": -1,
            "z": 1,
            "elements": [
                "minecraft:gold_block@0"
            ]
        },
        {
            "x": 0,
            "y": -1,
            "z": 3,
            "elements": [
                "minecraft:gold_block@0"
            ]
        },
        {
            "x": -1,
            "y": -1,
            "z": 5,
            "elements": [
                "minecraft:gold_block@0"
            ]
        },
        {
            "x": 1,
            "y": -1,
            "z": 3,
            "elements": [
                "minecraft:gold_block@0"
            ]
        },
        {
            "x": 3,
            "y": -1,
            "z": 1,
            
            "elements": [
                "modularmachinery:blockcasing@4"
            ]
        },
        {
            "x": 0,
            "y": -1,
            "z": 5,
            "elements": [
                "minecraft:gold_block@0"
            ]
        },
        {
            "x": 2,
            "y": -1,
            "z": 3,
            "elements": [
                "minecraft:gold_block@0"
            ]
        },
        {
            "x": 1,
            "y": -1,
            "z": 5,
            "elements": [
                "minecraft:gold_block@0"
            ]
        },
        {
            "x": 3,
            "y": -1,
            "z": 3,
            
            "elements": [
                "modularmachinery:blockcasing@4"
            ]
        },
        {
            "x": 2,
            "y": -1,
            "z": 5,
            "elements": [
                "minecraft:gold_block@0"
            ]
        },
        {
            "x": 3,
            "y": -1,
            "z": 5,
            
            "elements": [
                "modularmachinery:blockcasing@4"
            ]
        },
        {
            "x": -2,
            "y": 0,
            "z": 1,
            
            "elements": [
                "modularmachinery:blockcasing@0"
            ]
        },
        {
            "x": -1,
            "y": 0,
            "z": 1,
            
            "elements": [
                "modularmachinery:blockcasing@4"
            ]
        },
        {
            "x": 0,
            "y": 2,
            "z": 2,
            
            "elements": [
                "modularmachinery:blockcasing@3"
            ]
        },
        {
            "x": -2,
            "y": 0,
            "z": 3,
            
            "elements": [
                "modularmachinery:blockcasing@4"
            ]
        },
        {
            "x": 0,
            "y": 0,
            "z": 1,
            
            "elements": [
                "modularmachinery:blockcasing@4"
            ]
        },
        {
            "x": 1,
            "y": 0,
            "z": 1,
            
            "elements": [
                "modularmachinery:blockcasing@4"
            ]
        },
        {
            "x": -1,
            "y": 0,
            "z": 3,
            "elements": [
                "astralsorcery:fluidblockliquidstarlight@0"
            ]
        },
        {
            "x": 0,
            "y": 2,
            "z": 4,
            
            "elements": [
                "modularmachinery:blockcasing@3"
            ]
        },
        {
            "x": 2,
            "y": 0,
            "z": 1,
            
            "elements": [
                "modularmachinery:blockcasing@0"
            ]
        },
        {
            "x": -2,
            "y": 0,
            "z": 5,
            
            "elements": [
                "modularmachinery:blockcasing@0"
            ]
        },
        {
            "x": 0,
            "y": 0,
            "z": 3,
            "elements": [
                "astralsorcery:fluidblockliquidstarlight@0"
            ]
        },
        {
            "x": -1,
            "y": 0,
            "z": 5,
            
            "elements": [
                "modularmachinery:blockcasing@4"
            ]
        },
        {
            "x": 1,
            "y": 0,
            "z": 3,
            "elements": [
                "astralsorcery:fluidblockliquidstarlight@0"
            ]
        },
        {
            "x": 2,
            "y": 0,
            "z": 3,
            
            "elements": [
                "modularmachinery:blockcasing@4"
            ]
        },
        {
            "x": 0,
            "y": 0,
            "z": 5,
            
            "elements": [
                "modularmachinery:blockcasing@4"
            ]
        },
        {
            "x": 1,
            "y": 0,
            "z": 5,
            
            "elements": [
                "modularmachinery:blockcasing@4"
            ]
        },
        {
            "x": 2,
            "y": 0,
            "z": 5,
            
            "elements": [
                "modularmachinery:blockcasing@0"
            ]
        },
        {
            "x": -2,
            "y": 1,
            "z": 1,
            
            "elements": [
                "modularmachinery:blockcasing@0"
            ]
        },
        {
            "x": -3,
            "y": -1,
            "z": 2,
            
            "elements": [
                "modularmachinery:blockcasing@4"
            ]
        },
        {
            "x": -2,
            "y": -1,
            "z": 2,
            "elements": [
                "minecraft:gold_block@0"
            ]
        },
        {
            "x": -1,
            "y": -1,
            "z": 2,
            "elements": [
                "minecraft:gold_block@0"
            ]
        },
        {
            "x": -3,
            "y": -1,
            "z": 4,
            
            "elements": [
                "modularmachinery:blockcasing@4"
            ]
        },
        {
            "x": 2,
            "y": 1,
            "z": 1,
            
            "elements": [
                "modularmachinery:blockcasing@0"
            ]
        },
        {
            "x": -2,
            "y": 1,
            "z": 5,
            
            "elements": [
                "modularmachinery:blockcasing@0"
            ]
        },
        {
            "x": -2,
            "y": -1,
            "z": 4,
            "elements": [
                "minecraft:gold_block@0"
            ]
        },
        {
            "x": 0,
            "y": -1,
            "z": 2,
            "elements": [
                "minecraft:gold_block@0"
            ]
        },
        {
            "x": 1,
            "y": -1,
            "z": 2,
            "elements": [
                "minecraft:gold_block@0"
            ]
        },
        {
            "x": -1,
            "y": -1,
            "z": 4,
            "elements": [
                "minecraft:gold_block@0"
            ]
        },
        {
            "x": -3,
            "y": -1,
            "z": 6,
            
            "elements": [
                "modularmachinery:blockcasing@4"
            ]
        },
        {
            "x": 2,
            "y": -1,
            "z": 2,
            "elements": [
                "minecraft:gold_block@0"
            ]
        },
        {
            "x": 0,
            "y": -1,
            "z": 4,
            "elements": [
                "minecraft:gold_block@0"
            ]
        },
        {
            "x": -2,
            "y": -1,
            "z": 6,
            
            "elements": [
                "modularmachinery:blockcasing@4"
            ]
        },
        {
            "x": 1,
            "y": -1,
            "z": 4,
            "elements": [
                "minecraft:gold_block@0"
            ]
        },
        {
            "x": 3,
            "y": -1,
            "z": 2,
            
            "elements": [
                "modularmachinery:blockcasing@4"
            ]
        },
        {
            "x": -1,
            "y": -1,
            "z": 6,
            
            "elements": [
                "modularmachinery:blockcasing@4"
            ]
        },
        {
            "x": 2,
            "y": 1,
            "z": 5,
            
            "elements": [
                "modularmachinery:blockcasing@0"
            ]
        },
        {
            "x": 2,
            "y": -1,
            "z": 4,
            "elements": [
                "minecraft:gold_block@0"
            ]
        },
        {
            "x": 0,
            "y": -1,
            "z": 6,
            
            "elements": [
                "modularmachinery:blockcasing@4"
            ]
        },
        {
            "x": 3,
            "y": -1,
            "z": 4,
            
            "elements": [
                "modularmachinery:blockcasing@4"
            ]
        },
        {
            "x": 1,
            "y": -1,
            "z": 6,
            
            "elements": [
                "modularmachinery:blockcasing@4"
            ]
        },
        {
            "x": 2,
            "y": -1,
            "z": 6,
            
            "elements": [
                "modularmachinery:blockcasing@4"
            ]
        },
        {
            "x": 3,
            "y": -1,
            "z": 6,
            
            "elements": [
                "modularmachinery:blockcasing@4"
            ]
        },
        {
            "x": -2,
            "y": 2,
            "z": 1,
            "elements": [
                "additions:bxloveu-diamond_block@0"
            ]
        }
    ]}